Workbook

Sheet Overview
B2: This over view explaines the working of this file and how it feeds information to the online calculator.
B4: Each tab hold all the properties of componets to make up all the calculations required for making a roller shutter to a given spec.
B7: Any cell in red is to be checked

Sheet Online codes
A1: CODE | B1: Description | D1: Lath type | E1: Guide type | F1: Endlock type | G1: Reveal offsets | H1: Product class
A2: Y752 | B2: SeceuroDoor 75 22g - Industrial Motor Shutter | C2: 1 | H2: GAEC | K2: G=Guide
A3: Y750 | B3: SeceuroDoor 75 20g - Industrial Motor Shutter | C3: 2 | H3: GAEC | K3: B=boxsection
A4: Y077 | B4: SeceuroDoor 77 - Insulated Industrial Motor Shutter | C4: 3 | H4: GAEC | K4: EF = flat endplate
A5: Y100 | B5: SeceuroDoor 100 - Insulated Industrial Motor Shutter | C5: 5 | H5: GAEC | K5: EC = cranked endplate
A6: Y752 | B6: SeceuroDoor 75c 22g - Industrial Hand Chain Shutter | C6: 6 | K6: A = Angle
A7: Y750 | B7: SeceuroDoor 75c 20g - Industrial Hand Chain Shutter | C7: 7 | K7: RA = reveal angle
A8: Y077 | B8: SeceuroDoor 77c - Insulated Industrial Hand Chain Shutter | C8: 8
A9: YC752SM | B9: SeceuroDoor Continental 75 22g - Tube Motor Shutter | C9: 9
A10: YC752PM | B10: SeceuroDoor Continental 75 22g - Tube Motor, Full Vision Shutter | C10: 10
A11: YC750SM | B11: SeceuroDoor Continental 75 20g - Tube Motor Shutter | C11: 11
A12: YC750PM | B12: SeceuroDoor Continental 75 20g - Tube Motor Full Vision Shutter | C12: 12
A13: YT077SM | B13: SeceuroDoor Traditional 77t - Insulated Tube Motor Shutter | C13: 13
A14: YT752SM | B14: SeceuroDoor Traditional 75 22g - Tube Motor Shutter | C14: 14
A15: YT752PM | B15: SeceuroDoor Traditional 75 22g - Tube Motor Full Vision Shutter | C15: 15
A16: YT750SM | B16: SeceuroDoor Traditional 75 20g - Tube Motor Shutter | C16: 16
A17: YT750PM | B17: SeceuroDoor Traditional 75 20g - Tube Motor Full Vision Shutter | C17: 17
A18: YT8750 | B18: SeceuroDoor Traditional Plus 75 20g - Tube Motor Shutter | C18: 18
A19: YCOS | B19: SeceuroDoor Continental 75 22g - Spring Operated Shutter | C19: 19
... A36: YT750SME | B36: SeceuroDoor Traditional (EVO) 75 20g - Tube Motor Shutter | C36: 416

Sheet Lath
A1: Name | B1: Kgs/ m2 | C1: Lath weight / m length | D1: Compressed lath height | E1: uncompressed lath height | F1: Thickness | G1: Friction % | H1: max width | I1: min axle diameter | J1: max m2 | K1: vision percentage | L1: Lath image | M1: Wind | N1: Material | O1: Insulation value | P1: Product group | Q1: Wicket available | R1: Lath type
A2: 75mm 22swg, Solid 9.3kg/sqm | B2: 9.3 | D2: 74 | E2: 80 | F2: 17 | G2: 10 | H2: 4600 | I2: 100 | K2: 0 | M2: no | N2: Steel | O2: none | P2: Securodoor | Q2: Yes | R2: 75mm lath
A3: 75mm Wind 22swg Solid 9.3kg/sqm | B3: 9.3 | D3: 74 | E3: 80 | F3: 17 | G3: 15 | H3: 6200 | I3: 100 | K3: 0 | M3: Yes | N3: Steel | O3: none | P3: Securodoor | Q3: Yes | R3: 75mm lath
A4: 75mm 20swg, Solid 12.1kg/sqm | B4: 12.1 | D4: 74 | E4: 80 | F4: 17 | G4: 10 | H4: 4600 | I4: 100 | K4: 0 | M4: no | N4: Steel | O4: none | P4: Securodoor | Q4: Yes | R4: 75mm lath
A5: 75mm Wind 20swg Solid 12.1kg/sqm | B5: 12.1 | D5: 74 | E5: 80 | F5: 17 | G5: 15 | H5: 10000 | I5: 100 | K5: 0 | M5: Yes | N5: Steel | O5: none | P5: Securodoor | Q5: Yes | R5: 75mm lath
A6: 110mm 6/10 Solid | B6: 7.1090909 | C6: 0.782 | D6: 110 | E6: 112 | F6: 18 | G6: 20 | H6: 4500 | I6: 133 | K6: 0 | L6: #VALUE! | M6: Yes | N6: Steel | O6: none | P6: Murax | Q6: No | R6: 110mm
A7: 110mm 8/10 Solid | B7: 9.4181818 | C7: 1.036 | D7: 110 | E7: 112 | F7: 18 | G7: 20 | H7: 6000 | I7: 133 | K7: 0 | L7: #VALUE! | M7: Yes | N7: Steel | O7: none | P7: Murax | Q7: No | R7: 110mm
A8: 110mm 10/10 Solid | B8: 11.772727 | C8: 1.295 | D8: 110 | E8: 112 | F8: 18 | G8: 20 | H8: 10000 | I8: 133 | K8: 0 | L8: #VALUE! | M8: Yes | N8: Steel | O8: none | P8: Murax | Q8: No | R8: 110mm
A9: 110mm 12/10 Solid | B9: 14.127273 | C9: 1.554 | D9: 110 | E9: 112 | F9: 18 | G9: 20 | H9: 13500 | I9: 133 | K9: 0 | L9: #VALUE! | M9: Yes | N9: Steel | O9: none | P9: Murax | Q9: No | R9: 110mm
A10: 110mm 6/10 Solid | B10: 7.1090909 | C10: 0.782 | D10: 110 | E10: 112 | F10: 18 | G10: 20 | H10: 4500 | I10: 133 | K10: 0 | L10: #VALUE! | M10: NO | N10: Steel | O10: none | P10: Murax | Q10: No | R10: 110mm
A11: 110mm 8/10 Solid | B11: 9.4181818 | C11: 1.036 | D11: 110 | E11: 112 | F11: 18 | G11: 20 | H11: 6000 | I11: 133 | K11: 0 | L11: #VALUE! | M11: NO | N11: Steel | O11: none | P11: Murax | Q11: No | R11: 110mm
A12: 110mm 10/10 Solid | B12: 11.772727 | C12: 1.295 | D12: 110 | E12: 112 | F12: 18 | G12: 20 | H12: 10000 | I12: 133 | K12: 0 | L12: #VALUE! | M12: NO | N12: Steel | O12: none | P12: Murax | Q12: No | R12: 110mm
A13: 110mm 12/10 Solid | B13: 14.127273 | C13: 1.554 | D13: 110 | E13: 112 | F13: 18 | G13: 20 | H13: 13500 | I13: 133 | K13: 0 | L13: #VALUE! | M13: NO | N13: Steel | O13: none | P13: Murax | Q13: No | R13: 110mm
A14: 110mm 6/10 microperforated | B14: 5.5909091 | C14: 0.615 | D14: 110 | E14: 112 | F14: 18 | G14: 20 | H14: 4500 | I14: 133 | K14: 33 | L14: #VALUE! | M14: NO | N14: Steel | O14: none | P14: Murax | Q14: No | R14: 110mm
A15: 110mm 8/10 microperforated | B15: 7.4 | C15: 0.814 | D15: 110 | E15: 112 | F15: 18 | G15: 20 | H15: 6000 | I15: 133 | K15: 33 | L15: #VALUE! | M15: NO | N15: Steel | O15: none | P15: Murax | Q15: No | R15: 110mm
A16: 110mm 10/10 microperforated | B16: 9.2545455 | C16: 1.018 | D16: 110 | E16: 112 | F16: 18 | G16: 20 | H16: 1200 | I16: 133 | K16: 33 | L16: #VALUE! | M16: NO | N16: Steel | O16: none | P16: Murax | Q16: No | R16: 110mm

Sheet Bottom lath
A1: Bottom lath name | B1: BLath weight / m length | C1: BLath height | D1: Hangdown | E1: 75mm lath | F1: 95mm lath | G1: 100mm lath | H1: 110mm lath | I1: 77mm lath | J1: 55mm lath | K1: 150mm lath | L1: 38mm lath | M1: 60mm lath | N1: 80mm lath | O1: 90mm lath | P1: Sloping type
A3: T-Rail 3.2kg/m | B3: 3.2 | C3: 65 | D3: 50 | E3: Yes | F3: No | G3: No | H3: No | I3: No | J3: No | K3: No | L3: No | M3: No | N3: No | O3: No | P3: C section
A4: T-Rail with D-rubber 5.34kg/m | B4: =B3+1.64+0.5 -> 5.34 | C4: 90 | D4: 70 | E4: Yes | F4: No | G4: No | H4: No | I4: No | J4: No | K4: No | L4: No | M4: No | N4: No | O4: No | P4: C section
A5: FTFM Bottom Lath | B5: 2.873 | C5: 125 | D5: 80 | E5: No | F5: No | G5: No | H5: Yes | I5: No | J5: No | K5: No | L5: No | M5: No | N5: No | O5: No
A6: FTFM Bottom Lath with 1 angle reinforcement | B6: =B5+1.539 -> 4.412 | C6: 125 | D6: 80 | E6: No | F6: No | G6: No | H6: Yes | I6: No | J6: No | K6: No | L6: No | M6: No | N6: No | O6: No
A7: FTFM Bottom Lath with 2 angle reinforcement | B7: =B5+2*1.539 -> 5.951 | C7: 125 | D7: 80 | E7: No | F7: No | G7: No | H7: Yes | I7: No | J7: No | K7: No | L7: No | M7: No | N7: No | O7: No

Sheet Wind class
A3: Lath | B3: Manufacturer | C3: Guide | D3: Width | E3: Angle thickness | F3: Class
A6: 75mm 22g | B6: CRF | C6: 65 | D6: 4000 | E6: 3 | F6: 5
A7: 75mm 22g | B7: CRF | C7: 65 wind | D7: 5000 | E7: ? | F7: 5
A8: 75mm 22g perf | B8: CRF | C8: 65 | D8: 4000 | E8: 3 | F8: 5
A9: 75mm 20g | B9: CRF | C9: 65 wind | D9: 6000 | E9: ? | F9: 5
A10: 75mm 20g | B10: CRF | C10: 65 wind | D10: 8000 | E10: 6 | F10: 5
A11: 75mm 20g | B11: CRF | C11: 65 wind | D11: 10000 | E11: 6 | F11: 3
A13: 75mm 18g | B13: CRF | C13: 100 wind | D13: 10000 | E13: 6 | F13: 5
A14: 75mm 18g | B14: CRF | C14: 100 wind | D14: 12000 | E14: 6 | F14: 3
A17: 100mm | B17: CRF | C17: 90mm | D17: 10000 | E17: 6 | F17: 5
A19: 75mm 22g | B19: West Mercia | C19: 65 | D19: 4600 | E19: 3 | F19: 2
A20: 75mm 22g | B20: West Mercia | C20: 65 wind | D20: 6100 | E20: 3 | F20: 5
A21: 75mm 20g | B21: West Mercia | C21: 100 wind | D21: 8000 | E21: 5 | F21: 5

Sheet Endlock
B1: Description | C1: associated lath | D1: material | E1: weight in grams | F1: end lock offset | G1: endlock to guide inner | H1: Endlock type
B2: 75mm plastic | C2: 75mm | D2: plastic | E2: 20 | F2: 10 | G2: 9 | H2: Standard
B3: 75mm cast | C3: 75mm | D3: steel | E3: 60 | F3: 7.5 | G3: 9 | H3: Standard
B4: 75mm wind | C4: 75mm | D4: steel | E4: 235 | F4: 19 | G4: 9 | H4: Wind
B5: 77t plastic | C5: 77t | D5: plastic | E5: 10 | F5: 5 | G5: 9 | H5: Standard
B6: 110mm plastic if 60 guide | C6: 110mm | D6: plastic | E6: 0.024 | F6: 12 | G6: 8 | H6: Wind | J6: not compatible with 40 guide
B7: 110mm plastic if 80 guide | C7: 110mm | D7: plastic | E7: 0.024 | F7: 12 | G7: 13 | H7: Wind | J7: not compatible with 40 guide
B8: 110mm wind | C8: 110mm | D8: steel | E8: 0.151 | F8: 6 | G8: 6 | H8: Wind | J8: with FTFM 80 wind

Sheet Guides
A1: ID | B1: Name | C1: Wind type | D1: Width | E1: Penetration | F1: Material | I1: associated lath
A3: G65s | B3: 65 straight | C3: No | D3: 65 | E3: =D3-5 -> 60 | F3: Steel | I3: 75mm
A4: G65w | B4: 65 wind | C4: Yes | D4: 65 | E4: =D4-5 -> 60 | F4: Steel | I4: 75mm
A5: G100s | B5: 100 straight | C5: No | D5: 100 | E5: =D5-5 -> 95 | F5: Steel | I5: 75mm
A6: G100w | B6: 100 wind | C6: Yes | D6: 100 | E6: =D6-5 -> 95 | F6: Steel | I6: 75mm
A7: G80w | B7: 82 wind for 95mm | C7: Yes | D7: 82 | E7: =D7-5 -> 77 | F7: Steel | I7: 95mm
A8: G78w | B8: 78 for 100mm wind | C8: Yes | D8: 78 | E8: =D8-5 -> 73 | F8: Steel | I8: 100mm
A10: H17 | B10: H17 | C10: No | D10: 45 | E10: =17-5 -> 12 | F10: Aluminium
A11: H25 | B11: H25 | C11: No | D11: 53 | E11: =25-5 -> 20 | F11: Aluminium
A12: H30 | B12: H30 | C12: No | D12: 60 | E12: =31-7 -> 24 | F12: Aluminium
A13: H40s | B13: H40s wind | C13: Yes | D13: 70 | E13: =42-5 -> 37 | F13: Aluminium
A14: UPH140 | B14: UPH140 | C14: No | D14: 60 | E14: =32-5 -> 27 | F14: Aluminium
A15: UPH240 | B15: UPH240 | C15: No | D15: 75 | E15: =37-5 -> 32 | F15: Aluminium
A16: UPH250 | B16: UPH250 | C16: No | D16: 90 | E16: =52-5 -> 47 | F16: Aluminium
A18: FTFM 40 | B18: =A18 -> FTFM 40 | C18: No | D18: 40 | E18: 0 | F18: Steel | I18: 110mm
A20: FTFM 60 | B20: =A20 -> FTFM 60 | C20: No | D20: 60 | E20: 49.5 | F20: Steel | I20: 110mm
A21: FTFM 80 | B21: =A21 -> FTFM 80 | C21: No | D21: 80 | E21: 64.5 | F21: Steel | I21: 110mm
A23: FTFM 80 Wind | B23: =A23 -> FTFM 80 Wind | C23: Yes | D23: 80 | E23: =D23-Endlock!$F$8 -> 74 | F23: Steel | I23: 110mm

Sheet Axles
A1: Name | B1: Shape | C1: Alternate name | D1: Diameter | E1: Wall Thickness | F1: ID | G1: Material grade | H1: Density (kg/m3)
A2: 60mm x 1.2 | B2: Octagonal | C2: 60mm Oct | D2: 60 | E2: 1.2 | F2: =D2-(E2*2) -> 57.6 | G2: 190000 | H2: 7850
A3: 70mm x 1.2 | B3: Octagonal | C3: 70mm Oct | D3: 70 | E3: 1.2 | F3: =D3-(E3*2) -> 67.6 | G3: 190000 | H3: 7850
A4: 70mm 1.5 | B4: Octagonal | C4: 70mm Oct | D4: 70 | E4: 1.5 | F4: =D4-(E4*2) -> 67 | G4: 190000 | H4: 7850
A5: 102 x 1.6 | B5: Circular | C5: 4" 16 g | D5: 102 | E5: 1.6 | F5: =D5-(E5*2) -> 98.8 | G5: 190000 | H5: 7850
A6: 102 x 3.6 | B6: Circular | C6: 4" 10g | D6: 102 | E6: 3.6 | F6: =D6-(E6*2) -> 94.8 | G6: 190000 | H6: 7850
A7: 127 x 3.2 | B7: Circular | C7: 5" 10g | D7: 127 | E7: 3.25 | F7: =D7-(E7*2) -> 120.5 | G7: 210000 | H7: 7850
A8: 139 x 4.8 | B8: Circular | C8: 5.5" 6g | D8: 139 | E8: 4.8 | F8: =D8-(E8*2) -> 129.4 | G8: 210000 | H8: 7850
A9: 168 x 4.8 | B9: Circular | C9: 6 5/8th" 6g | D9: 168 | E9: 4.8 | F9: =D9-(E9*2) -> 158.4 | G9: 210000 | H9: 7850
A10: 193 x 6.3 | B10: Circular | C10: 7 5/8th" 3g | D10: 193 | E10: 6.3 | F10: =D10-(E10*2) -> 180.4 | G10: 190000 | H10: 7850
A11: 219 x 5.9 | B11: Circular | C11: 8 5/8" 3g | D11: 219 | E11: 6.3 | F11: =D11-(E11*2) -> 206.4 | G11: 190000 | H11: 7850
A12: 273 x 5.89 | B12: Circular | C12: 10 3/4" 3g | D12: 273.05 | E12: 5.89 | F12: =D12-(E12*2) -> 261.27 | G12: 199000 | H12: 7850
A13: 273 x 8 | B13: Circular | C13: 10 3/4" 8mm | D13: 273.05 | E13: 8 | F13: =D13-(E13*2) -> 257.05 | G13: 199000 | H13: 7850
A14: 133 x 2.5 | B14: Circular | C14: 133.25 | D14: 133 | E14: 2.5 | F14: =D14-(2*E14) -> 128 | G14: 240000 | H14: 7850
A15: 133 x 3 | B15: Circular | C15: 133.30 | D15: 133 | E15: 3 | F15: =D15-(2*E15) -> 127 | G15: 240000 | H15: 7850
A16: 168 x 3 | B16: Circular | C16: 168.30 | D16: 168 | E16: 3 | F16: =D16-(2*E16) -> 162 | G16: 240000 | H16: 7850

Sheet Disc size
A1: Barrel size | B1: Barrel size mm | C1: Barrel ID | D1: Disc to barrel gap | E1: Disc o/d | F1: Disc thickness | G1: Disc bore | H1: Stock ref | I1: SWS stock | J1: Supplier | K1: Supplier ref | L1: circ
A3: 4" 16 | B3: 102 x 1.6 | C3: =Axles!F5 -> 98.8 | D3: =(E3-C3)/2 -> -0.65 | E3: 97.5 | F3: 5 | G3: 25.4 | J3: GFA | L3: =PI() * G3 -> 79.796453 | N3: =L3/25.4 -> 3.1415927
A4: 4" 16 | B4: 102 x 1.6 | C4: =Axles!F5 -> 98.8 | D4: =(E4-C4)/2 -> -0.65 | E4: 97.5 | F4: 5 | G4: 30 | I4: SD141B2 | J4: GFA | L4: =PI() * G4 -> 94.24778 | N4: =L4/25.4 -> 3.7105425
A5: 4" 16 | B5: 102 x 1.6 | C5: =Axles!F5 -> 98.8 | D5: =(E5-C5)/2 -> -0.65 | E5: 97.5 | F5: 5 | G5: 35 | J5: GFA | L5: =PI() * G5 -> 109.95574 | N5: =L5/25.4 -> 4.3289663
A6: 4" 10 | B6: 102 x 3.6 | C6: =Axles!F6 -> 94.8 | D6: =(E6-C6)/2 -> -0.9 | E6: 93 | F6: 5 | G6: 25.4 | J6: GFA | L6: =PI() * G6 -> 79.796453 | N6: =L6/25.4 -> 3.1415927
A7: 4" 10 | B7: 102 x 3.6 | C7: =Axles!F6 -> 94.8 | D7: =(E7-C7)/2 -> -0.9 | E7: 93 | F7: 5 | G7: 30 | I7: SD142B1 | J7: GFA | L7: =PI() * G7 -> 94.24778 | N7: =L7/25.4 -> 3.7105425
A8: 4" 10 | B8: 102 x 3.6 | C8: =Axles!F6 -> 94.8 | D8: =(E8-C8)/2 -> -0.9 | E8: 93 | F8: 5 | G8: 35 | J8: GFA | L8: =PI() * G8 -> 109.95574 | N8: =L8/25.4 -> 4.3289663
A9: 4" 10 | B9: 102 x 3.6 | C9: =Axles!F6 -> 94.8 | D9: =(E9-C9)/2 -> -0.9 | E9: 93 | F9: 5 | G9: 40 | I9: MT229M2 | J9: GFA | L9: =PI() * G9 -> 125.66371 | N9: =L9/25.4 -> 4.94739
A10: 4" 10 | B10: 102 x 3.6 | C10: =Axles!F6 -> 94.8 | D10: =(E10-C10)/2 -> -0.9 | E10: 93 | F10: 5 | G10: 45 | J10: GFA | L10: =PI() * G10 -> 141.37167 | N10: =L10/25.4 -> 5.5658138
A11: 5" 10g | B11: 127 x 3.2 | C11: =Axles!F7 -> 120.5 | D11: =(E11-C11)/2 -> -0.25 | E11: 120 | F11: 5 | G11: 25.4 | J11: GFA | L11: =PI() * G11 -> 79.796453 | N11: =L11/25.4 -> 3.1415927
A12: 5" 10g | B12: 127 x 3.2 | C12: =Axles!F7 -> 120.5 | D12: =(E12-C12)/2 -> -0.25 | E12: 120 | F12: 5 | G12: 30 | I12: SD141B3 | J12: GFA | L12: =PI() * G12 -> 94.24778 | N12: =L12/25.4 -> 3.7105425
A13: 5" 10g | B13: 127 x 3.2 | C13: =Axles!F7 -> 120.5 | D13: =(E13-C13)/2 -> -0.25 | E13: 120 | F13: 5 | G13: 35 | J13: GFA | L13: =PI() * G13 -> 109.95574 | N13: =L13/25.4 -> 4.3289663
A14: 5" 10g | B14: 127 x 3.2 | C14: =Axles!F7 -> 120.5 | D14: =(E14-C14)/2 -> -0.25 | E14: 120 | F14: 5 | G14: 40 | I14: MT204M1 | J14: GFA | L14: =PI() * G14 -> 125.66371 | N14: =L14/25.4 -> 4.94739
A15: 5" 10g | B15: 127 x 3.2 | C15: =Axles!F7 -> 120.5 | D15: =(E15-C15)/2 -> -0.25 | E15: 120 | F15: 5 | G15: 45 | J15: GFA | L15: =PI() * G15 -> 141.37167 | N15: =L15/25.4 -> 5.5658138
A16: 5.5" 6g | B16: 139 x 4.8 | C16: =Axles!F8 -> 129.4 | D16: =(E16-C16)/2 -> -0.45 | E16: 128.5 | F16: 5 | G16: 30 | I16: SD141B4 | J16: GFA | L16: =PI() * G16 -> 94.24778 | N16: =L16/25.4 -> 3.7105425
A17: 5.5" 6g | B17: 139 x 4.8 | C17: =Axles!F8 -> 129.4 | D17: =(E17-C17)/2 -> -0.45 | E17: 128.5 | F17: 5 | G17: 35 | J17: GFA | L17: =PI() * G17 -> 109.95574 | N17: =L17/25.4 -> 4.3289663
A18: 5.5" 6g | B18: 139 x 4.8 | C18: =Axles!F8 -> 129.4 | D18: =(E18-C18)/2 -> -0.45 | E18: 128.5 | F18: 5 | G18: 40 | I18: MT205M1 | J18: GFA | L18: =PI() * G18 -> 125.66371 | N18: =L18/25.4 -> 4.94739
A19: 5.5" 6g | B19: 139 x 4.8 | C19: =Axles!F8 -> 129.4 | D19: =(E19-C19)/2 -> -0.45 | E19: 128.5 | F19: 5 | G19: 45 | J19: GFA | L19: =PI() * G19 -> 141.37167 | N19: =L19/25.4 -> 5.5658138
A20: 5.5" 6g | B20: 139 x 4.8 | C20: =Axles!F8 -> 129.4 | D20: =(E20-C20)/2 -> -0.45 | E20: 128.5 | F20: 5 | G20: 55 | I20: MT232M1 | J20: GFA | L20: =PI() * G20 -> 172.7876 | N20: =L20/25.4 -> 6.8026613
A21: 6 5/8th" 6g | B21: 168 x 4.8 | C21: =Axles!F9 -> 158.4 | D21: =(E21-C21)/2 -> -1.7 | E21: 155 | F21: 8 | G21: 40 | J21: GFA | L21: =PI() * G21 -> 125.66371 | N21: =L21/25.4 -> 4.94739
A22: 6 5/8th" 6g | B22: 168 x 4.8 | C22: =Axles!F9 -> 158.4 | D22: =(E22-C22)/2 -> -1.7 | E22: 155 | F22: 8 | G22: 45 | J22: GFA | L22: =PI() * G22 -> 141.37167 | N22: =L22/25.4 -> 5.5658138
A23: 6 5/8th" 6g | B23: 168 x 4.8 | C23: =Axles!F9 -> 158.4 | D23: =(E23-C23)/2 -> -1.7 | E23: 155 | F23: 8 | G23: 55 | J23: GFA | L23: =PI() * G23 -> 172.7876 | N23: =L23/25.4 -> 6.8026613
A24: 6 5/8th" 6g | B24: 168 x 4.8 | C24: =Axles!F9 -> 158.4 | D24: =(E24-C24)/2 -> -0.2 | E24: 158 | F24: 8 | G24: 30 | J24: GFA | L24: =PI() * G24 -> 94.24778 | N24: =L24/25.4 -> 3.7105425
A25: 6 5/8th" 6g | B25: 168 x 4.8 | C25: =Axles!F9 -> 158.4 | D25: =(E25-C25)/2 -> -0.2 | E25: 158 | F25: 8 | G25: 35 | J25: GFA | L25: =PI() * G25 -> 109.95574 | N25: =L25/25.4 -> 4.3289663
A26: 6 5/8th" 6g | B26: 168 x 4.8 | C26: =Axles!F9 -> 158.4 | D26: =(E26-C26)/2 -> -0.2 | E26: 158 | F26: 8 | G26: 40 | J26: GFA | L26: =PI() * G26 -> 125.66371 | N26: =L26/25.4 -> 4.94739
A27: 6 5/8th" 6g | B27: 168 x 4.8 | C27: =Axles!F9 -> 158.4 | D27: =(E27-C27)/2 -> -0.2 | E27: 158 | F27: 8 | G27: 45 | J27: GFA | L27: =PI() * G27 -> 141.37167 | N27: =L27/25.4 -> 5.5658138
A28: 6 5/8th" 6g | B28: 168 x 4.8 | C28: =Axles!F9 -> 158.4 | D28: =(E28-C28)/2 -> -0.2 | E28: 158 | F28: 8 | G28: 55 | J28: GFA | L28: =PI() * G28 -> 172.7876 | N28: =L28/25.4 -> 6.8026613
A29: 6 5/8th" 6g | B29: 168 x 4.8 | C29: =Axles!F9 -> 158.4 | D29: =(E29-C29)/2 -> 1.3 | E29: 161 | F29: 8 | G29: 30 | J29: GFA | L29: =PI() * G29 -> 94.24778 | N29: =L29/25.4 -> 3.7105425
A30: 6 5/8th" 6g | B30: 168 x 4.8 | C30: =Axles!F9 -> 158.4 | D30: =(E30-C30)/2 -> 1.3 | E30: 161 | F30: 8 | G30: 35 | J30: GFA | L30: =PI() * G30 -> 109.95574 | N30: =L30/25.4 -> 4.3289663
A31: 6 5/8th" 6g | B31: 168 x 4.8 | C31: =Axles!F9 -> 158.4 | D31: =(E31-C31)/2 -> 1.3 | E31: 161 | F31: 8 | G31: 40 | J31: GFA | L31: =PI() * G31 -> 125.66371 | N31: =L31/25.4 -> 4.94739
A32: 6 5/8th" 6g | B32: 168 x 4.8 | C32: =Axles!F9 -> 158.4 | D32: =(E32-C32)/2 -> 1.3 | E32: 161 | F32: 8 | G32: 45 | J32: GFA | L32: =PI() * G32 -> 141.37167 | N32: =L32/25.4 -> 5.5658138
A33: 6 5/8th" 6g | B33: 168 x 4.8 | C33: =Axles!F9 -> 158.4 | D33: =(E33-C33)/2 -> 1.3 | E33: 161 | F33: 8 | G33: 55 | J33: GFA | L33: =PI() * G33 -> 172.7876 | N33: =L33/25.4 -> 6.8026613
A34: 7 5/8th" 3g | B34: 193 x 6.3 | C34: =Axles!F10 -> 180.4 | D34: =(E34-C34)/2 -> -0.2 | E34: 180 | F34: 8 | G34: 40 | J34: GFA | L34: =PI() * G34 -> 125.66371 | N34: =L34/25.4 -> 4.94739
A35: 7 5/8th" 3g | B35: 193 x 6.3 | C35: =Axles!F10 -> 180.4 | D35: =(E35-C35)/2 -> -0.2 | E35: 180 | F35: 8 | G35: 45 | J35: GFA | L35: =PI() * G35 -> 141.37167 | N35: =L35/25.4 -> 5.5658138
A36: 7 5/8th" 3g | B36: 193 x 6.3 | C36: =Axles!F10 -> 180.4 | D36: =(E36-C36)/2 -> -0.2 | E36: 180 | F36: 8 | G36: 50 | J36: GFA | L36: =PI() * G36 -> 157.07963 | N36: =L36/25.4 -> 6.1842375
A37: 7 5/8th" 3g | B37: 193 x 6.3 | C37: =Axles!F10 -> 180.4 | D37: =(E37-C37)/2 -> -0.2 | E37: 180 | F37: 8 | G37: 55 | J37: GFA | L37: =PI() * G37 -> 172.7876 | N37: =L37/25.4 -> 6.8026613
A38: 7 5/8th" 3g | B38: 193 x 6.3 | C38: =Axles!F10 -> 180.4 | D38: =(E38-C38)/2 -> -0.2 | E38: 180 | F38: 8 | G38: 60 | J38: GFA | L38: =PI() * G38 -> 188.49556 | N38: =L38/25.4 -> 7.421085
A39: 8 5/8" 3g | B39: 219 x 5.9 | C39: =Axles!F11 -> 206.4 | D39: =(E39-C39)/2 -> -3.7 | E39: 199 | F39: 8 | G39: 50 | J39: GFA | L39: =PI() * G39 -> 157.07963 | N39: =L39/25.4 -> 6.1842375
A40: 8 5/8" 3g | B40: 219 x 5.9 | C40: =Axles!F11 -> 206.4 | D40: =(E40-C40)/2 -> -3.7 | E40: 199 | F40: 8 | G40: 55 | J40: GFA | L40: =PI() * G40 -> 172.7876 | N40: =L40/25.4 -> 6.8026613
A41: 8 5/8" 3g | B41: 219 x 5.9 | C41: =Axles!F11 -> 206.4 | D41: =(E41-C41)/2 -> -3.7 | E41: 199 | F41: 8 | G41: 60 | J41: GFA | L41: =PI() * G41 -> 188.49556 | N41: =L41/25.4 -> 7.421085
...

Sheet Motors
A1: Name | B1: Manufacturer | C1: Torque (Nm) min | D1: Torque (Nm) max | E1: Usage type | F1: RPM | G1: Voltage | H1: Mounting type | I1: Head offset | J1: Motor Total Length | K1: Tube diameter | L1: Driveshaft diameter mm | M1: Requires additional saftey brake | N1: Manual override | O1: Limit turn | P1: Cycles Per Hour | Q1: Weight | R1: Wattage | S1: SWS Code | T1: Motor Image | U1: Price for ref | V1: Comments
A2: NRG 50 | B2: Ellard | C2: 0 | D2: 50 | E2: Standard | F2: 12 | G2: 230 | H2: Tubular | I2: 26 | J2: 605 | K2: 45 | L2: N/A | M2: Yes | N2: No | O2: 22 | Q2: 3 | R2: 310
A3: NRG 50 with override | B3: Ellard | C3: 0 | D3: 50 | E3: Standard | F3: 12 | G3: 230 | H3: Tubular | I3: 23 | J3: 544 | K3: 45 | L3: N/A | M3: Yes | N3: Yes | O3: 22 | Q3: 3.3 | R3: 310
A4: NRG 100 | B4: Ellard | C4: 50.01 | D4: 100 | E4: Standard | F4: 12 | G4: 230 | H4: Tubular | K4: 59 | L4: N/A | M4: Yes | N4: No | O4: 22 | Q4: 5 | R4: 345
A5: NRG 100 with override | B5: Ellard | C5: 50.01 | D5: 100 | E5: Standard | F5: 12 | G5: 230 | H5: Tubular | K5: 59 | L5: N/A | M5: Yes | N5: Yes | O5: 22 | Q5: 5.2 | R5: 345
A6: NRG 150 | B6: Ellard | C6: 100.01 | D6: 150 | E6: Standard | F6: 10 | G6: 230 | H6: Tubular | K6: 59 | L6: N/A | M6: Yes | N6: No | O6: 22 | Q6: 8 | R6: 390
A7: NRG 150 with override | B7: Ellard | C7: 100.01 | D7: 150 | E7: Standard | F7: 10 | G7: 230 | H7: Tubular | K7: 59 | L7: N/A | M7: Yes | N7: Yes | O7: 22 | Q7: 8.3 | R7: 390
A8: NRG 230 with override | B8: Ellard | C8: 150.01 | D8: 230 | E8: Standard | F8: 6 | G8: 230 | H8: Tubular | K8: 92 | L8: N/A | M8: Yes | N8: Yes | O8: 22 | Q8: 12 | R8: 570
A9: NRG 350 with override | B9: Ellard | C9: 230.01 | D9: 350 | E9: Standard | F9: 7 | G9: 230 | H9: Tubular | K9: 92 | L9: N/A | M9: Yes | N9: Yes | O9: 22 | Q9: 14 | R9: 670
A10: - | B10: - | C10: - | D10: - | H10: -- | N10: --
A11: T845M | B11: Simu | C11: =D9+0.01 -> 350.01 | D11: 450 | E11: Standard | F11: 8 | G11: 230 | H11: Tubular | I11: 85 | K11: 89 | L11: N/A | M11: Yes | N11: YES | O11: 15 | Q11: 16 | R11: 1200
A12: T960M | B12: Simu | C12: =D11+0.01 -> 450.01 | D12: 600 | E12: Standard | F12: 9 | G12: 230 | H12: Tubular | I12: 83 | K12: 89 | L12: N/A | M12: Yes | N12: No | Q12: 19 | R12: 920
A13: T815M | B13: Simu | C13: 0.01 | D13: 150 | E13: Standard | F13: 8 | G13: 230 | H13: Tubular | I13: 69 | K13: 80 | M13: Yes | N13: Yes | O13: 17 | Q13: 12 | R13: 500 | T13: #VALUE!
A14: T820M | B14: Simu | C14: 150.01 | D14: 200 | E14: Standard | F14: 8 | G14: 230 | H14: Tubular | I14: 69 | K14: 80 | M14: Yes | N14: Yes | O14: 17 | Q14: 13.4 | R14: 620 | T14: #VALUE!
A15: T825M | B15: Simu | C15: 200.01 | D15: 250 | E15: Standard | F15: 8 | G15: 230 | H15: Tubular | I15: 69 | K15: 80 | M15: Yes | N15: Yes | O15: 21 | Q15: 14 | R15: 680 | T15: #VALUE!
A16: T830M | B16: Simu | C16: 250.01 | D16: 300 | E16: Standard | F16: 8 | G16: 230 | H16: Tubular | I16: 68 | K16: 89 | M16: Yes | N16: Yes | O16: 17 | Q16: 13.3 | R16: 855 | T16: #VALUE!
A17: T835M | B17: Simu | C17: 300.01 | D17: 350 | E17: Standard | F17: 8 | G17: 230 | H17: Tubular | I17: 85 | K17: 89 | M17: Yes | N17: Yes | O17: 15 | Q17: 19.6 | R17: 990 | T17: #VALUE!
A18: - | B18: - | C18: - | D18: - | H18: -- | N18: --
A19: Jet 10 | B19: Somfy | C19: 0 | D19: 10 | E19: Standard | F19: 32 | G19: 230 | H19: Tubular | I19: 23 | J19: 555 | K19: 48 | L19: N/A | M19: Yes | N19: No | O19: 46 | Q19: 2.44 | R19: 160
A20: Meteor 20 CSI | B20: Somfy | C20: =D19+0.01 -> 10.01 | D20: 20 | E20: Standard | F20: 17 | G20: 230 | H20: Tubular | I20: 28 | J20: 774 | K20: 48 | L20: N/A | M20: Yes | N20: Yes | O20: 34 | Q20: 2.76 | R20: 160
A21: Gemini 25 | B21: Somfy | C21: =D20+0.01 -> 20.01 | D21: 25 | E21: Standard | F21: 17 | G21: 230 | H21: Tubular | J21: 663 | K21: 48 | L21: N/A | M21: Yes | N21: No | O21: 46 | Q21: 3.09 | R21: 180
A22: Helios 30 | B22: Somfy | C22: =D21+0.01 -> 25.01 | D22: 30 | E22: Standard | F22: 12 | G22: 230 | H22: Tubular | K22: 48 | L22: N/A | M22: Yes | N22: Yes | O22: 46 | Q22: 3.2 | R22: 240
A23: Helios 30 CSI | B23: Somfy | C23: =C22 -> 25.01 | D23: 30 | E23: Standard | F23: 17 | G23: 230 | H23: Tubular | K23: 48 | L23: N/A | M23: Yes | N23: Yes | O23: 34 | Q23: 3.2 | R23: 240
A24: Apollo 35 | B24: Somfy | C24: =D22+0.01 -> 30.01 | D24: 35 | E24: Standard | F24: 17 | G24: 230 | H24: Tubular | K24: 48 | L24: N/A | M24: Yes | N24: No | O24: 46 | Q24: 3.38 | R24: 270
A25: Mariner 40 CSI | B25: Somfy | C25: =D24+0.01 -> 35.01 | D25: 40 | E25: Standard | F25: 17 | G25: 230 | H25: Tubular | K25: 48 | L25: N/A | M25: Yes | N25: Yes | O25: 34 | Q25: 3.38 | R25: 270
A26: Vectran 50 | B26: Somfy | C26: =D25+0.01 -> 40.01 | D26: 50 | E26: Standard | F26: 12 | G26: 230 | H26: Tubular | K26: 48 | L26: N/A | M26: Yes | N26: No | O26: 46 | Q26: 3.09 | R26: 240
A27: ORION 55 CSI | B27: Somfy | C27: =D26+0.01 -> 50.01 | D27: 55 | E27: Standard | F27: 17 | G27: 230 | H27: Tubular | J27: 800 | K27: 60 | L27: N/A | M27: Yes | N27: Yes | O27: 34 | Q27: 4.17 | R27: 290
A28: Vega 60 CSI | B28: Somfy | C28: =D27+0.01 -> 55.01 | D28: 60 | E28: Standard | F28: 12 | G28: 230 | H28: Tubular | J28: 646 | K28: 60 | L28: N/A | M28: Yes | N28: Yes | O28: 34 | Q28: 3.92 | R28: 320
A29: Sirius 80 CSI | B29: Somfy | C29: =D28+0.01 -> 60.01 | D29: 80 | E29: Standard | F29: 12 | G29: 230 | H29: Tubular | K29: 60 | L29: N/A | M29: Yes | N29: Yes | O29: 34 | Q29: 4.19 | R29: 290
A30: Jupiter 85 | B30: Somfy | C30: =D29+0.01 -> 80.01 | D30: 85 | E30: Standard | F30: 17 | G30: 230 | H30: Tubular | K30: 60 | L30: N/A | M30: Yes | N30: No | O30: 34 | Q30: 4.45 | R30: 450
A31: Titan 100 CSI | B31: Somfy | C31: =D30+0.01 -> 85.01 | D31: 100 | E31: Standard | F31: 12 | G31: 230 | H31: Tubular | J31: 681 | K31: 60 | L31: N/A | M31: Yes | N31: Yes | O31: 34 | Q31: 4.68 | R31: 410
A32: Taurus 120 CSI | B32: Somfy | C32: =D31+0.01 -> 100.01 | D32: 120 | E32: Standard | F32: 12 | G32: 230 | H32: Tubular | J32: 681 | K32: 60 | L32: N/A | M32: Yes | N32: Yes | O32: 34 | Q32: 4.45 | R32: 450
A33: - | B33: - | C33: - | D33: - | H33: -- | N33: --
A34: DDO 300 | B34: Ellard | C34: 0 | D34: 300 | E34: Standard | F34: 12 | G34: 230 | H34: Direct drive | I34: N/A | K34: N/A | L34: 40 | M34: No | N34: -- | R34: 900 | S34: NO CODE
A35: - | B35: - | H35: -- | N35: --
A36: DDO 170 | B36: Ellard | C36: 0 | D36: 170 | E36: Standard | F36: 12 | G36: 415 | H36: Direct drive | I36: N/A | K36: N/A | L36: 30 | M36: No | N36: Yes | R36: 900 | S36: MT417M3
A37: DDO 260 | B37: Ellard | C37: 170.01 | D37: 260 | E37: Standard | F37: 12 | G37: 415 | H37: Direct drive | I37: N/A | K37: N/A | L37: 40 | M37: No | N37: Yes | R37: 900 | S37: MT426M3
A38: DDO 350 | B38: Ellard | C38: 260.01 | D38: 350 | E38: Standard | F38: 12 | G38: 415 | H38: Direct drive | I38: N/A | K38: N/A | L38: 40 | M38: No | N38: Yes | R38: 900 | S38: MT435M3
A39: DD0 500 | B39: Ellard | C39: 351.01 | D39: 500 | E39: Standard | F39: 12 | G39: 415 | H39: Direct drive | I39: N/A | K39: N/A | L39: 40 | M39: No | N39: Yes | R39: 900 | S39: MT450M3
A40: DD0 650 | B40: Ellard | C40: 500.01 | D40: 650 | E40: Standard | F40: 12 | G40: 415 | H40: Direct drive | I40: N/A | K40: N/A | L40: 55 | M40: No | N40: Yes | R40: 1800 | S40: MT465M3
...

Sheet Chaindrive
A1: Motor Description | B1: Manufacturer | C1: Sprocket teeth | D1: Sprocket bore | E1: Plate wheel | F1: Plate bore | G1: Gear ratio | H1: chain size | I1: Motor nm | J1: effective nm | K1: RPM | L1: effective RPM | M1: Voltage | N1: Limit turns | O1: Limit turn ratio adjustement | P1: Sprocket diameter | Q1: Platewheel Diameter | R1: Driveshaft diameter mm | S1: Chain Breaking Strain in newtons | U1: Comments
A4: Ranger 70 1ph 19-57 1/2" | B4: GFA | C4: 19 | D4: 25.4 | E4: 57 | F4: 30 | G4: =E4/C4 -> 3 | H4: 1/2" | I4: 70 | J4: =I4*G4 -> 210 | K4: 32 | L4: =K4/G4 -> 10.666667 | M4: 230 | N4: 40 | O4: =N4/G4 -> 13.333333 | P4: 77.16 | Q4: 230 | R4: 25.4 | S4: 18000
A5: Ranger 70 1ph 15-57 1/2" | B5: GFA | C5: 15 | D5: 25.4 | E5: 57 | F5: 30 | G5: =E5/C5 -> 3.8 | H5: 1/2" | I5: 70 | J5: =I5*G5 -> 266 | K5: 32 | L5: =K5/G5 -> 8.4210526 | M5: 230 | N5: 40 | O5: =N5/G5 -> 10.526316 | P5: 61.09 | Q5: 230 | S5: 18000
P6: -
A7: Ranger 90 1ph 19-57 1/2" | B7: GFA | C7: 19 | D7: 25.4 | E7: 57 | F7: 30 | G7: =E7/C7 -> 3 | H7: 1/2" | I7: 90 | J7: =I7*G7 -> 270 | K7: 24 | L7: =K7/G7 -> 8 | M7: 230 | N7: 40 | O7: =N7/G7 -> 13.333333 | P7: 77.16 | Q7: 230 | R7: 25.4 | S7: 18000
A8: Ranger 90 1ph 15-57 1/2" | B8: GFA | C8: 15 | D8: 25.4 | E8: 57 | F8: 30 | G8: =E8/C8 -> 3.8 | H8: 1/2" | I8: 90 | J8: =I8*G8 -> 342 | K8: 24 | L8: =K8/G8 -> 6.3157895 | M8: 230 | N8: 40 | O8: =N8/G8 -> 10.526316 | P8: 61.09 | Q8: 230 | R8: 25.4 | S8: 18000
P9: -
A10: Ranger 90 3ph 19-57 1/2" | B10: GFA | C10: 19 | D10: 25.4 | E10: 57 | F10: 30 | G10: =E10/C10 -> 3 | H10: 1/2" | I10: 90 | J10: =I10*G10 -> 270 | K10: 32 | L10: =K10/G10 -> 10.666667 | M10: 415 | N10: 40 | O10: =N10/G10 -> 13.333333 | P10: 77.16 | Q10: 230 | R10: 25.4 | S10: 18000
A11: Ranger 90 3ph 15-57 1/2" | B11: GFA | C11: 15 | D11: 25.4 | E11: 57 | F11: 30 | G11: =E11/C11 -> 3.8 | H11: 1/2" | I11: 90 | J11: =I11*G11 -> 342 | K11: 32 | L11: =K11/G11 -> 8.4210526 | M11: 415 | N11: 40 | O11: =N11/G11 -> 10.526316 | P11: 61.09 | Q11: 230 | R11: 25.4 | S11: 18000
P12: -
A13: Ranger150 3ph 18-57 5/8" | B13: GFA | C13: 18 | D13: 25.4 | E13: 57 | F13: 30 | G13: =E13/C13 -> 3.1666667 | H13: 5/8" | I13: 149 | J13: =I13*G13 -> 471.83333 | K13: 47 | L13: =K13/G13 -> 14.842105 | M13: 415 | N13: 40 | O13: =N13/G13 -> 12.631579 | P13: 91.42 | Q13: 288 | R13: 25.4 | S13: 22400
A14: Ranger150 3ph 15-57 5/8" | B14: GFA | C14: 15 | D14: 25.4 | E14: 57 | F14: 30 | G14: =E14/C14 -> 3.8 | H14: 5/8" | I14: 150 | J14: =I14*G14 -> 570 | K14: 48 | L14: =K14/G14 -> 12.631579 | M14: 415 | N14: 40 | O14: =N14/G14 -> 10.526316 | P14: 91.42 | Q14: 288 | R14: 25.4 | S14: 22400
A15: Ranger150 3ph 12-57 5/8" | B15: GFA | C15: 12 | D15: 25.4 | E15: 57 | F15: 40 | G15: =E15/C15 -> 4.75 | H15: 5/8" | I15: 150 | J15: =I15*G15 -> 712.5 | K15: 48 | L15: =K15/G15 -> 10.105263 | M15: 415 | N15: 40 | O15: =N15/G15 -> 8.4210526 | P15: 73.6 | Q15: 288 | R15: 25.4 | S15: 22400
P16: -
A17: Ranger220 3ph 15-57 3/4" | B17: GFA | C17: 15 | D17: 30 | E17: 57 | F17: 30 | G17: =E17/C17 -> 3.8 | H17: 3/4" | I17: 220 | J17: =I17*G17 -> 836 | K17: 24 | L17: =K17/G17 -> 6.3157895 | M17: 415 | N17: 40 | O17: =N17/G17 -> 10.526316 | P17: 115.75 | Q17: 345.81 | R17: 25.4 | S17: 22400
P18: -
A20: Ranger 90 Fi 1ph 15-57 1/2" | B20: GFA | C20: 15 | D20: 25.4 | E20: 57 | F20: 30 | G20: =E20/C20 -> 3.8 | H20: 1/2" | I20: 90 | J20: =I20*G20 -> 342 | K20: 80 | L20: =K20/G20 -> 21.052632 | M20: 230 | N20: 20 | O20: =N20/G20 -> 5.2631579 | P20: 61.09 | Q20: 230 | R20: 25.4 | S20: 18000
A21: Ranger 90 Fi 3ph 15-57 1/2" | B21: GFA | C21: 15 | D21: 25.4 | E21: 57 | F21: 30 | G21: =E21/C21 -> 3.8 | H21: 1/2" | I21: 90 | J21: =I21*G21 -> 342 | K21: 80 | L21: =K21/G21 -> 21.052632 | M21: 415 | N21: 20 | O21: =N21/G21 -> 5.2631579 | P21: 61.09 | Q21: 230 | R21: 25.4 | S21: 18000
A22: Ranger140 Fi 1ph 18-57 5/8" | B22: GFA | C22: 18 | D22: 25.4 | E22: 57 | F22: 30 | G22: =E22/C22 -> 3.1666667 | H22: 5/8" | I22: 150 | J22: =I22*G22 -> 475 | K22: 80 | L22: =K22/G22 -> 25.263158 | M22: 230 | N22: 20 | O22: =N22/G22 -> 6.3157895 | P22: 91.42 | Q22: 288 | R22: 25.4 | S22: 22400
A23: Ranger140 Fi 3ph 18-57 5/8" | B23: GFA | C23: 18 | D23: 25.4 | E23: 57 | F23: 30 | G23: =E23/C23 -> 3.1666667 | H23: 5/8" | I23: 150 | J23: =I23*G23 -> 475 | K23: 80 | L23: =K23/G23 -> 25.263158 | M23: 415 | N23: 20 | O23: =N23/G23 -> 6.3157895 | P23: 91.42 | Q23: 288 | R23: 25.4 | S23: 22400
A24: Ranger140 fi 1ph 12-57 5/8" | B24: GFA | C24: 12 | D24: 25.4 | E24: 57 | F24: 40 | G24: =E24/C24 -> 4.75 | H24: 5/8" | I24: 150 | J24: =I24*G24 -> 712.5 | K24: 80 | L24: =K24/G24 -> 16.842105 | M24: 230 | N24: 20 | O24: =N24/G24 -> 4.2105263 | P24: 73.6 | Q24: 288 | R24: 25.4 | S24: 22400
A25: Ranger140 fi 3ph 12-57 5/8" | B25: GFA | C25: 12 | D25: 25.4 | E25: 57 | F25: 40 | G25: =E25/C25 -> 4.75 | H25: 5/8" | I25: 150 | J25: =I25*G25 -> 712.5 | K25: 80 | L25: =K25/G25 -> 16.842105 | M25: 415 | N25: 20 | O25: =N25/G25 -> 4.2105263 | P25: 73.6 | Q25: 288 | R25: 25.4 | S25: 22400
A28: KE 40.24 15-57 3/4" | B28: GFA | C28: 15 | D28: 40 | E28: 57 | F28: 40 | G28: =E28/C28 -> 3.8 | H28: 3/4" | I28: 400 | J28: =I28*G28 -> 1520 | K28: 24 | L28: =K28/G28 -> 6.3157895 | M28: 415 | N28: 40 | O28: =N28/G28 -> 10.526316 | P28: 192.91 | Q28: 461 | R28: =D28 -> 40 | S28: 60000
A29: KE 40.24 15-57 1" | B29: GFA | C29: 15 | D29: 40 | E29: 57 | F29: 40 | G29: =E29/C29 -> 3.8 | H29: 1" | I29: 400 | J29: =I29*G29 -> 1520 | K29: 24 | L29: =K29/G29 -> 6.3157895 | M29: 415 | N29: 40 | O29: =N29/G29 -> 10.526316 | P29: 192.91 | Q29: 461 | R29: =D29 -> 40 | S29: 60000
A30: KE 60.24 15-57 1" | B30: GFA | C30: 15 | D30: 55 | E30: 57 | F30: 55 | G30: =E30/C30 -> 3.8 | H30: 1" | I30: 600 | J30: =I30*G30 -> 2280 | K30: 24 | L30: =K30/G30 -> 6.3157895 | M30: 415 | N30: 60 | O30: =N30/G30 -> 15.789474 | P30: 192.91 | Q30: 461 | R30: =D30 -> 55 | S30: 60000
A31: KE 80.24 15-57 1" | B31: GFA | C31: 15 | D31: 55 | E31: 57 | F31: 55 | G31: =E31/C31 -> 3.8 | H31: 1" | I31: 800 | J31: =I31*G31 -> 3040 | K31: 24 | L31: =K31/G31 -> 6.3157895 | M31: 415 | N31: 60 | O31: =N31/G31 -> 15.789474 | P31: 152.72 | Q31: 576 | R31: =D31 -> 55 | S31: 95000
A32: KE 80.24 15-57 1 1/4" | B32: GFA | C32: 15 | D32: 55 | E32: 57 | F32: 55 | G32: =E32/C32 -> 3.8 | H32: 1 1/4" | I32: 800 | J32: =I32*G32 -> 3040 | K32: 24 | L32: =K32/G32 -> 6.3157895 | M32: 415 | N32: 60 | O32: =N32/G32 -> 15.789474 | P32: 152.72 | Q32: 576 | R32: =D32 -> 55 | S32: 95000
A35: KE 40.40 Fi 15-57 3/4" | B35: GFA | C35: 15 | D35: 40 | E35: 57 | F35: 40 | G35: =E35/C35 -> 3.8 | H35: 3/4" | I35: 300 | J35: =I35*G35 -> 1140 | K35: 40 | L35: =K35/G35 -> 10.526316 | M35: 230/415 | N35: 40 | O35: =N35/G35 -> 10.526316 | P35: 115.75 | Q35: 345.81 | R35: 40 | S35: 29000
A36: KE 40.40 Fi 15-57 1" | B36: GFA | C36: 15 | D36: 40 | E36: 57 | F36: 40 | G36: =E36/C36 -> 3.8 | H36: 1" | I36: 300 | J36: =I36*G36 -> 1140 | K36: 40 | L36: =K36/G36 -> 10.526316 | M36: 230/415 | N36: 40 | O36: =N36/G36 -> 10.526316 | P36: 115.75 | Q36: 345.81 | R36: 40 | S36: 29000
A37: KE 50.80 Fi 15-57 1" | B37: GFA | C37: 15 | D37: 55 | E37: 57 | F37: 55 | G37: =E37/C37 -> 3.8 | H37: 1" | I37: 500 | J37: =I37*G37 -> 1900 | K37: 80 | L37: =K37/G37 -> 21.052632 | M37: 230/415 | N37: 60 | O37: =N37/G37 -> 15.789474 | P37: 115.75 | Q37: 345.81 | R37: 55 | S37: 60000
A38: KE 80.40 Fi 15-57 1" | B38: GFA | C38: 15 | D38: 55 | E38: 57 | F38: 55 | G38: =E38/C38 -> 3.8 | H38: 1" | I38: 800 | J38: =I38*G38 -> 3040 | K38: 40 | L38: =K38/G38 -> 10.526316 | M38: 230/415 | N38: 60 | O38: =N38/G38 -> 15.789474 | P38: 115.75 | Q38: 345.81 | R38: 55 | S38: 60000
A39: KE 80.40 Fi 15-57 1 1/4" | B39: GFA | C39: 15 | D39: 55 | E39: 57 | F39: 55 | G39: =E39/C39 -> 3.8 | H39: 1 1/4" | I39: 800 | J39: =I39*G39 -> 3040 | K39: 40 | L39: =K39/G39 -> 10.526316 | M39: 230/415 | N39: 60 | O39: =N39/G39 -> 15.789474 | P39: 115.75 | Q39: 345.81 | R39: 55 | S39: 60000
A41: JM200 | B41: Ellard | C41: 11 | D41: 25.4 | E41: 61 | G41: =E41/C41 -> 5.5454545 | H41: 1/2" | I41: 20 | J41: =I41*G41 -> 110.90909 | K41: 34 | L41: =K41/G41 -> 6.1311475 | M41: 415 | R41: 25.4 | S41: 18000
A42: JM500 | B42: Ellard | C42: 9 | E42: 50 | G42: =E42/C42 -> 5.5555556 | H42: 5/8" | I42: 62 | J42: =I42*G42 -> 344.44444 | K42: 34 | L42: =K42/G42 -> 6.12 | M42: 415 | S42: 22400
A43: JM750 | B43: Ellard | C43: 10 | E43: 64 | G43: =E43/C43 -> 6.4 | H43: 5/8" | I43: 95 | J43: =I43*G43 -> 608 | K43: 22 | L43: =K43/G43 -> 3.4375 | M43: 415 | S43: 22400
A44: JM1000 | B44: Ellard | C44: 9 | E44: 57 | G44: =E44/C44 -> 6.3333333 | H44: 3/4" | I44: 128 | J44: =I44*G44 -> 810.66667 | K44: 22 | L44: =K44/G44 -> 3.4736842 | M44: 415 | S44: 29000
A45: JM1500 | B45: Ellard | C45: 11 | E45: 48 | G45: =E45/C45 -> 4.3636364 | H45: 1" | I45: 369 | J45: =I45*G45 -> 1610.1818 | K45: 15 | L45: =K45/G45 -> 3.4375 | M45: 415
A46: JM2200 | C46: 14 | E46: 72 | G46: =E46/C46 -> 5.1428571 | H46: 1/2" | I46: 428 | J46: =I46*G46 -> 2201.1429 | K46: 16.5 | L46: =K46/G46 -> 3.2083333 | M46: 415 | R46: 25.4 | S46: 18000
A48: JM150 | B48: Ellard | C48: 19 | D48: 25.4 | E48: 57 | G48: =E48/C48 -> 3 | H48: 1/2" | I48: 15 | J48: =I48*G48 -> 45 | K48: 34 | L48: =K48/G48 -> 11.333333 | M48: 230 | R48: 25.4 | S48: 18000
A49: JM500 | B49: Ellard | C49: 19 | D49: 25.4 | E49: 57 | G49: =E49/C49 -> 3 | H49: 1/2" | I49: 62 | J49: =I49*G49 -> 186 | K49: 34 | L49: =K49/G49 -> 11.333333 | M49: 230 | R49: 25.4 | S49: 18000
...

Sheet Chain
A1: Chain Size | B1: Sprocket Size (no. Teeth) | C1: Sprocket Bore size mm | D1: Platewheel Size (no. Teeth) | E1: Platewheel Bore size mm | F1: Chain Breaking Strain | G1: Pitch (mm) | H1: Breaking Strain in n | I1: Ratio | J1: Platewheel diameter
A2: 1/2" | B2: 12 | C2: 25.4 | D2: 57 | E2: 30 | F2: 18000 | G2: =0.5*25.4 -> 12.7 | H2: 17999 | I2: =D2/B2 -> 4.75 | J2: 230.54
A3: 1/2" | B3: 15 | C3: 25.4 | D3: 57 | E3: 30 | F3: 18000 | G3: =0.5*25.4 -> 12.7 | H3: 18000 | I3: =D3/B3 -> 3.8 | J3: 230.54
A4: 1/2" | B4: 19 | C4: 25.4 | D4: 57 | E4: 30 | F4: 18000 | G4: =0.5*25.4 -> 12.7 | H4: 18000 | I4: =D4/B4 -> 3 | J4: 230.54
A5: 5/8" | B5: 12 | C5: 25.4 | D5: 57 | E5: 30/40 | F5: 22400 | G5: =0.625*25.4 -> 15.875 | H5: 22400 | I5: =D5/B5 -> 4.75 | J5: 288.18
A6: 5/8" | B6: 18 | C6: 25.4 | D6: 57 | E6: 30/40 | F6: 22400 | G6: =0.625*25.4 -> 15.875 | H6: 22400 | I6: =D6/B6 -> 3.1666667 | J6: 288.18
A7: 3/4" | B7: 12 | C7: 25.4 | D7: 57 | E7: 40/50 | F7: 29000 | G7: =0.75*25.4 -> 19.05 | H7: 29000 | I7: =D7/B7 -> 4.75 | J7: 345.81
A8: 3/4" | B8: 12 | C8: 30 | D8: 57 | E8: 40/50 | F8: 29000 | G8: =0.75*25.4 -> 19.05 | H8: 29000 | I8: =D8/B8 -> 4.75 | J8: 345.81
A9: 3/4" | B9: 15 | C9: 30 | D9: 57 | E9: 40/50 | F9: 29000 | G9: =0.75*25.4 -> 19.05 | H9: 29000 | I9: =D9/B9 -> 3.8 | J9: 345.81
A10: 1" | B10: 15 | C10: 40 | D10: 57 | E10: 50/60/80 | F10: 60000 | G10: 25.4 | H10: 60000 | I10: =D10/B10 -> 3.8 | J10: 461.07
A11: 1 1/4" | B11: 15 | C11: 55 | D11: 57 | E11: 60/80 | F11: 95000 | G11: =1.25*25.4 -> 31.75 | H11: 95000 | I11: =D11/B11 -> 3.8 | J11: 576.36

Sheet Bearings
A1: Bearing name | B1: Shaft size in mm | C1: newtons | D1: load capacity in kgs | E1: Manufacture | F1: Part No | G1: Bearing image
A2: UCFL206 - 4 hole 30mm | B2: 30 | C2: 5900 | D2: =C2*0.1019716213 -> 601.63257 | E2: Ellard
A3: UCF208 - 4 hole 40mm | B3: 40 | C3: 10800 | D3: =C3*0.1019716213 -> 1101.2935 | E3: Ellard
A4: UCFL206 - 4 hole 30mm | B4: 30 | C4: 11250 | D4: =C4*0.1019716213 -> 1147.1807 | E4: GFA | F4: B/UFC206
A5: UCF208 - 4 hole 40mm | B5: 40 | C5: 18100 | D5: =C5*0.1019716213 -> 1845.6863 | E5: GFA | F5: B/UFC208
A6: UCF211- 4 hole 55mm | B6: 55 | C6: 29200 | D6: =C6*0.1019716213 -> 2977.5713 | E6: GFA | F6: B/UFC211
A7: UCF212 - 4 hole 60mm | B7: 60 | C7: 32800 | D7: =C7*0.1019716213 -> 3344.6692 | E7: GFA | F7: B/UFC212
B8: 80 | E8: Other

Sheet SafetyB
A1: Name | B1: Operating Torque (Nm) | C1: Max Safety Torque (Nm) | D1: Max Locking Speed (RPM) | E1: Manufacture | F1: Door max weight in kgs on 100mm axle | G1: Driveshaft diameter mm | H1: Stop distance | I1: SB image | J1: SWS stock code | K1: Notes
A2: RD80 | B2: 95 | C2: 545 | D2: 22 | E2: Timmer | G2: 18s | H2: 10
A3: RD150 | B3: 147 | C3: 812 | D3: 22 | E3: Timmer | G3: 18s | H3: 10
A4: TA 1/2 RD | B4: 332 | C4: 796 | D4: 22 | E4: Timmer | F4: 480 | G4: 30 | H4: 10 | K4: We use Ellard at this size
A5: TA 2/3 RD | B5: 552 | C5: 1253 | D5: 22 | E5: Timmer | G5: 40 | H5: 10 | K5: We use Ellard at this size
A6: FG 80 -40 | B6: 800 | C6: 2330 | D6: 24 | E6: GFA | G6: 40 | H6: 10
A7: FG 120 -50 | B7: 1200 | C7: 3530 | D7: 24 | E7: GFA | G7: 50 | H7: 10
A8: FG 220 -60 | B8: 2200 | C8: 6691 | D8: 15 | E8: GFA | G8: 60 | H8: 10 | K8: shaft type? Keyed type 2? What is that?
A9: FG 360 - 80 | B9: 3600 | C9: 10260 | D9: 15 | E9: GFA | G9: 80 | H9: 10 | K9: Out side our current scope required.
A10: RSB-G | B10: 130 | C10: 276 | D10: 22 | E10: Ellard | G10: 18s | H10: 10
A11: GDB 18 | B11: 145 | C11: 365 | D11: 22 | E11: Ellard | F11: 200 | G11: 18s | H11: 10
A12: RSB 1 / 2 (RSB1-30) | B12: 332 | C12: 1444 | D12: 22 | E12: Ellard | F12: 460 | G12: 30 | H12: 10
A13: RSB 2 / 3 (RSB1-40) | B13: 542 | C13: 1863 | D13: 22 | E13: Ellard | G13: 40 | H13: 10
A14: RSB 4 (PCM10A) | B14: 1000 | C14: 3560 | D14: 12 | E14: Ellard | G14: 50 | H14: 10
A16: RSB-1-18a | B16: 145 | C16: 365 | D16: 22 | E16: Marantec | F16: 200 | G16: 18s | H16: 10
A18: FTFM RSB1-30 | B18: 368 | C18: 1444 | D18: 22 | E18: HuZhou SIMPLE Technology | G18: 30 | I18: #VALUE!
A19: FTFM RSB1-40 | B19: 650 | C19: 2058 | D19: 22 | E19: HuZhou SIMPLE Technology | G19: 40 | I19: #VALUE!

Sheet Endplate
A1: Name | B1: Size | C1: Max load kgs | D1: Material | E1: Thickness mm | F1: Fixing holes | G1: Offset
A3: EVO 300 (40) | B3: 300 | C3: 500 | D3: Steel | E3: 3 | F3: =B3-50 -> 250 | G3: 40
A4: EVO 350 (40) | B4: 350 | C4: 450 | D4: Steel | E4: 3 | F4: =B4-50 -> 300 | G4: 40
A5: EVO 400 (40) | B5: 400 | C5: 550 | D5: Steel | E5: 4 | F5: =B5-50 -> 350 | G5: 40
A6: EVO 450 (40) | B6: 450 | C6: 550 | D6: Steel | E6: 4 | F6: =B6-50 -> 400 | G6: 40
A7: EVO 300 (60) | B7: 300 | C7: 500 | D7: Steel | E7: 3 | F7: =B7-50 -> 250 | G7: 60
A8: EVO 350 (60) | B8: 350 | C8: 450 | D8: Steel | E8: 3 | F8: =B8-50 -> 300 | G8: 60
A9: EVO 400 (60) | B9: 400 | C9: 550 | D9: Steel | E9: 4 | F9: =B9-50 -> 350 | G9: 60
A10: EVO 450 (60) | B10: 450 | C10: 550 | D10: Steel | E10: 4 | F10: =B10-50 -> 400 | G10: 60
A13: Industrial 300 | B13: 300 | C13: 700 | D13: Steel | E13: 6 | F13: =B13-50 -> 250 | G13: 92
A14: Industrial 350 | B14: 350 | C14: 650 | D14: Steel | E14: 6 | F14: =B14-50 -> 300 | G14: 92
A15: Industrial 400 | B15: 400 | C15: 1200 | D15: Steel | E15: 8 | F15: =B15-50 -> 350 | G15: 92
A16: Industrial 450 | B16: 450 | C16: 1100 | D16: Steel | E16: 8 | F16: =B16-50 -> 400 | G16: 92
... A35: 350 Ali | B35: 350 | C35: 50 | D35: Aluminium | E35: 10 | F35: =B35-50 -> 300 | G35: 0
A37: FTFM 280 | B37: 280 | C37: 450 | D37: steel | E37: 3 | G37: 0
A38: FTFM 310 | B38: 310 | C38: 450 | D38: steel | E38: 3 | G38: 0
A39: FTFM 340 | B39: 340 | C39: 450 | D39: steel | E39: 3 | G39: 0
A40: FTFM 370 | B40: 370 | C40: 450 | D40: steel | E40: 3 | G40: 0
A41: FTFM 400 | B41: 400 | C41: 450 | D41: steel | E41: 3 | G41: 0
A42: FTFM 440 | B42: 440 | C42: 450 | D42: Steel | E42: 3 | G42: 0
C44: for a pair of plates

Sheet Wicket doors
A1: Name | B1: Height | C1: Width
A2: Standard | B2: 1650 | C2: 550
A3: Euro door | B3: 1875 | C3: 750

Sheet Size range
A2: Sizes to be confimed, this is to test logic.
A4: Clear opening | B4: operation | C4: Min width | D4: Max width | E4: Min height | F4: Max height
A5: 75mm 22g | B5: Tube motor | C5: 1000 | D5: 6000 | E5: 500 | F5: 6000
A6: 75mm 20g | B6: Tube motor | C6: 1000 | D6: 8200 | E6: 500 | F6: 8000
A7: 75mm 18g | B7: Tube motor | C7: 1000 | D7: 9000 | E7: 500 | F7: 8000
A8: 95mm | B8: Tube motor | C8: 1000 | D8: 9000 | E8: 500 | F8: 8000
A9: 100mm | B9: Tube motor | C9: 1000 | D9: 9000 | E9: 500 | F9: 8000
A11: 75mm 22g | B11: Industrial motor | C11: 1000 | D11: 6000 | E11: 500 | F11: 6000
A12: 75mm 20g | B12: Industrial motor | C12: 1000 | D12: 8200 | E12: 500 | F12: 8000
A13: 75mm 18g | B13: Industrial motor | C13: 1000 | D13: 9000 | E13: 500 | F13: 8000
A14: 95mm | B14: Industrial motor | C14: 1000 | D14: 9000 | E14: 500 | F14: 8000
A15: 100mm | B15: Industrial motor | C15: 1000 | D15: 9000 | E15: 500 | F15: 8000
A17: 75mm 22g | B17: Spring | C17: 1000 | D17: 6000 | E17: 500 | F17: 3000
A18: 75mm 20g | B18: Spring | C18: 1000 | D18: 4000 | E18: 500 | F18: 3000
... A21: 100mm | B21: Spring | C21: 1000 | D21: 2000 | E21: 500 | F21: 3000
A23: 75mm 22g | B23: Chain
A24: 75mm 20g | B24: Chain
A25: 75mm 18g | B25: Chain
A26: 95mm | B26: Chain
A27: 100mm | B27: Chain
